Workbook

Sheet Base de Vidas
A1: T/D/A | B1: Nome | C1: Sexo | D1: Nascimento | E1: Idade | F1: Faixa 2 | G1: Plano | H1: Valor | I1: Parentesco | J1: Cidade | K1: UF | L1: Situação | M1: CID | N1: Empresa
A2: T | B2: ANDERSON MANOEL DA SILVA | C2: =IF(ISERROR(SEARCH(" ",TRIM(B2),1)),VLOOKUP(TRIM(B2),[1]!sDados,2,FALSE),VLOOKUP(TRIM(MID(TRIM(B2),1,SEARCH(" ",TRIM(B2),1))),[1]!sDados,2,FALSE)) | E2: 42 | F2: =IF(E2<=18,"00 - 18",IF(E2<=23,"19 - 23",IF(E2<=28,"24 - 28",IF(E2<=33,"29 - 33",IF(E2<=38,"34 - 38",IF(E2<=43,"39 - 43",IF(E2<=48,"44 - 48",IF(E2<=53,"49 - 53",IF(E2<=58,"54 - 58",IF(E2>=59,"59 - ou mais")))))))))) | G2: AMIL S380 QP NAC R COPART PJ | H2: 440.65
A3: T | B3: FABIO GOMES JERONIMO | C3: =IF(ISERROR(SEARCH(" ",TRIM(B3),1)),VLOOKUP(TRIM(B3),[1]!sDados,2,FALSE),VLOOKUP(TRIM(MID(TRIM(B3),1,SEARCH(" ",TRIM(B3),1))),[1]!sDados,2,FALSE)) | E3: 43 | F3: =IF(E3<=18,"00 - 18",IF(E3<=23,"19 - 23",IF(E3<=28,"24 - 28",IF(E3<=33,"29 - 33",IF(E3<=38,"34 - 38",IF(E3<=43,"39 - 43",IF(E3<=48,"44 - 48",IF(E3<=53,"49 - 53",IF(E3<=58,"54 - 58",IF(E3>=59,"59 - ou mais")))))))))) | G3: AMIL S380 QP NAC R COPART PJ | H3: 440.65
A4: D | B4: JULIANA NOGUEIRA RODRIGUES JERONIMO | C4: =IF(ISERROR(SEARCH(" ",TRIM(B4),1)),VLOOKUP(TRIM(B4),[1]!sDados,2,FALSE),VLOOKUP(TRIM(MID(TRIM(B4),1,SEARCH(" ",TRIM(B4),1))),[1]!sDados,2,FALSE)) | E4: 39 | F4: =IF(E4<=18,"00 - 18",IF(E4<=23,"19 - 23",IF(E4<=28,"24 - 28",IF(E4<=33,"29 - 33",IF(E4<=38,"34 - 38",IF(E4<=43,"39 - 43",IF(E4<=48,"44 - 48",IF(E4<=53,"49 - 53",IF(E4<=58,"54 - 58",IF(E4>=59,"59 - ou mais")))))))))) | G4: AMIL S380 QP NAC R COPART PJ | H4: 440.65 | I4: Conjuge
A5: D | B5: GUSTAVO RODRIGUES GOMES JERONIMO | C5: =IF(ISERROR(SEARCH(" ",TRIM(B5),1)),VLOOKUP(TRIM(B5),[1]!sDados,2,FALSE),VLOOKUP(TRIM(MID(TRIM(B5),1,SEARCH(" ",TRIM(B5),1))),[1]!sDados,2,FALSE)) | E5: 14 | F5: =IF(E5<=18,"00 - 18",IF(E5<=23,"19 - 23",IF(E5<=28,"24 - 28",IF(E5<=33,"29 - 33",IF(E5<=38,"34 - 38",IF(E5<=43,"39 - 43",IF(E5<=48,"44 - 48",IF(E5<=53,"49 - 53",IF(E5<=58,"54 - 58",IF(E5>=59,"59 - ou mais")))))))))) | G5: AMIL S380 QP NAC R COPART PJ | H5: 440.65 | I5: Filho/Filha
A6: D | B6: PEDRO HENRIQUE GOMES JERONIMO DIAS | C6: =IF(ISERROR(SEARCH(" ",TRIM(B6),1)),VLOOKUP(TRIM(B6),[1]!sDados,2,FALSE),VLOOKUP(TRIM(MID(TRIM(B6),1,SEARCH(" ",TRIM(B6),1))),[1]!sDados,2,FALSE)) | E6: 17 | F6: =IF(E6<=18,"00 - 18",IF(E6<=23,"19 - 23",IF(E6<=28,"24 - 28",IF(E6<=33,"29 - 33",IF(E6<=38,"34 - 38",IF(E6<=43,"39 - 43",IF(E6<=48,"44 - 48",IF(E6<=53,"49 - 53",IF(E6<=58,"54 - 58",IF(E6>=59,"59 - ou mais")))))))))) | G6: AMIL S380 QP NAC R COPART PJ | H6: 440.65 | I6: Filho/Filha
A7: D | B7: YASMIN VITORIA SOARES E SILVA | C7: =IF(ISERROR(SEARCH(" ",TRIM(B7),1)),VLOOKUP(TRIM(B7),[1]!sDados,2,FALSE),VLOOKUP(TRIM(MID(TRIM(B7),1,SEARCH(" ",TRIM(B7),1))),[1]!sDados,2,FALSE)) | E7: 19 | F7: =IF(E7<=18,"00 - 18",IF(E7<=23,"19 - 23",IF(E7<=28,"24 - 28",IF(E7<=33,"29 - 33",IF(E7<=38,"34 - 38",IF(E7<=43,"39 - 43",IF(E7<=48,"44 - 48",IF(E7<=53,"49 - 53",IF(E7<=58,"54 - 58",IF(E7>=59,"59 - ou mais")))))))))) | G7: AMIL S380 QP NAC R COPART PJ | H7: 440.65 | I7: Filho/Filha
A8: T | B8: MATHEUS DA GRACACORREA | C8: =IF(ISERROR(SEARCH(" ",TRIM(B8),1)),VLOOKUP(TRIM(B8),[1]!sDados,2,FALSE),VLOOKUP(TRIM(MID(TRIM(B8),1,SEARCH(" ",TRIM(B8),1))),[1]!sDados,2,FALSE)) | E8: 27 | F8: =IF(E8<=18,"00 - 18",IF(E8<=23,"19 - 23",IF(E8<=28,"24 - 28",IF(E8<=33,"29 - 33",IF(E8<=38,"34 - 38",IF(E8<=43,"39 - 43",IF(E8<=48,"44 - 48",IF(E8<=53,"49 - 53",IF(E8<=58,"54 - 58",IF(E8>=59,"59 - ou mais")))))))))) | G8: AMIL S380 QC NAC R COPART PJ | H8: 396.78
A9: D | B9: ARIELLA DA GRACACORREA | C9: =IF(ISERROR(SEARCH(" ",TRIM(B9),1)),VLOOKUP(TRIM(B9),[1]!sDados,2,FALSE),VLOOKUP(TRIM(MID(TRIM(B9),1,SEARCH(" ",TRIM(B9),1))),[1]!sDados,2,FALSE)) | E9: 7 | F9: =IF(E9<=18,"00 - 18",IF(E9<=23,"19 - 23",IF(E9<=28,"24 - 28",IF(E9<=33,"29 - 33",IF(E9<=38,"34 - 38",IF(E9<=43,"39 - 43",IF(E9<=48,"44 - 48",IF(E9<=53,"49 - 53",IF(E9<=58,"54 - 58",IF(E9>=59,"59 - ou mais")))))))))) | G9: AMIL S380 QC NAC R COPART PJ | H9: 396.78 | I9: Filho/Filha
A10: T | B10: MARLON MAURICIO CORREA DO ROSARIO | C10: =IF(ISERROR(SEARCH(" ",TRIM(B10),1)),VLOOKUP(TRIM(B10),[1]!sDados,2,FALSE),VLOOKUP(TRIM(MID(TRIM(B10),1,SEARCH(" ",TRIM(B10),1))),[1]!sDados,2,FALSE)) | E10: 27 | F10: =IF(E10<=18,"00 - 18",IF(E10<=23,"19 - 23",IF(E10<=28,"24 - 28",IF(E10<=33,"29 - 33",IF(E10<=38,"34 - 38",IF(E10<=43,"39 - 43",IF(E10<=48,"44 - 48",IF(E10<=53,"49 - 53",IF(E10<=58,"54 - 58",IF(E10>=59,"59 - ou mais")))))))))) | G10: AMIL S380 QC NAC R COPART PJ | H10: 396.78
A11: T | B11: MATHEUS SILVA HELLMANN | C11: =IF(ISERROR(SEARCH(" ",TRIM(B11),1)),VLOOKUP(TRIM(B11),[1]!sDados,2,FALSE),VLOOKUP(TRIM(MID(TRIM(B11),1,SEARCH(" ",TRIM(B11),1))),[1]!sDados,2,FALSE)) | E11: 21 | F11: =IF(E11<=18,"00 - 18",IF(E11<=23,"19 - 23",IF(E11<=28,"24 - 28",IF(E11<=33,"29 - 33",IF(E11<=38,"34 - 38",IF(E11<=43,"39 - 43",IF(E11<=48,"44 - 48",IF(E11<=53,"49 - 53",IF(E11<=58,"54 - 58",IF(E11>=59,"59 - ou mais")))))))))) | G11: AMIL S380 QC NAC R COPART PJ | H11: 396.78
A12: T | B12: DANIEL DA SILVA ORTIZ | C12: =IF(ISERROR(SEARCH(" ",TRIM(B12),1)),VLOOKUP(TRIM(B12),[1]!sDados,2,FALSE),VLOOKUP(TRIM(MID(TRIM(B12),1,SEARCH(" ",TRIM(B12),1))),[1]!sDados,2,FALSE)) | E12: 42 | F12: =IF(E12<=18,"00 - 18",IF(E12<=23,"19 - 23",IF(E12<=28,"24 - 28",IF(E12<=33,"29 - 33",IF(E12<=38,"34 - 38",IF(E12<=43,"39 - 43",IF(E12<=48,"44 - 48",IF(E12<=53,"49 - 53",IF(E12<=58,"54 - 58",IF(E12>=59,"59 - ou mais")))))))))) | G12: AMIL S380 QC NAC R COPART PJ | H12: 396.78
A13: D | B13: MARCIA CRISTINA LEAL DA SILVA ORTIZ | C13: =IF(ISERROR(SEARCH(" ",TRIM(B13),1)),VLOOKUP(TRIM(B13),[1]!sDados,2,FALSE),VLOOKUP(TRIM(MID(TRIM(B13),1,SEARCH(" ",TRIM(B13),1))),[1]!sDados,2,FALSE)) | E13: 32 | F13: =IF(E13<=18,"00 - 18",IF(E13<=23,"19 - 23",IF(E13<=28,"24 - 28",IF(E13<=33,"29 - 33",IF(E13<=38,"34 - 38",IF(E13<=43,"39 - 43",IF(E13<=48,"44 - 48",IF(E13<=53,"49 - 53",IF(E13<=58,"54 - 58",IF(E13>=59,"59 - ou mais")))))))))) | G13: AMIL S380 QC NAC R COPART PJ | H13: 396.78 | I13: Conjuge
A14: T | B14: MAILSON POLLNOW | C14: =IF(ISERROR(SEARCH(" ",TRIM(B14),1)),VLOOKUP(TRIM(B14),[1]!sDados,2,FALSE),VLOOKUP(TRIM(MID(TRIM(B14),1,SEARCH(" ",TRIM(B14),1))),[1]!sDados,2,FALSE)) | E14: 32 | F14: =IF(E14<=18,"00 - 18",IF(E14<=23,"19 - 23",IF(E14<=28,"24 - 28",IF(E14<=33,"29 - 33",IF(E14<=38,"34 - 38",IF(E14<=43,"39 - 43",IF(E14<=48,"44 - 48",IF(E14<=53,"49 - 53",IF(E14<=58,"54 - 58",IF(E14>=59,"59 - ou mais")))))))))) | G14: AMIL S380 QC NAC R COPART PJ | H14: 396.78
A15: D | B15: PRISCILA ROSANA HAUSS POLLNOW | C15: =IF(ISERROR(SEARCH(" ",TRIM(B15),1)),VLOOKUP(TRIM(B15),[1]!sDados,2,FALSE),VLOOKUP(TRIM(MID(TRIM(B15),1,SEARCH(" ",TRIM(B15),1))),[1]!sDados,2,FALSE)) | E15: 32 | F15: =IF(E15<=18,"00 - 18",IF(E15<=23,"19 - 23",IF(E15<=28,"24 - 28",IF(E15<=33,"29 - 33",IF(E15<=38,"34 - 38",IF(E15<=43,"39 - 43",IF(E15<=48,"44 - 48",IF(E15<=53,"49 - 53",IF(E15<=58,"54 - 58",IF(E15>=59,"59 - ou mais")))))))))) | G15: AMIL S380 QC NAC R COPART PJ | H15: 396.78 | I15: Conjuge
A16: D | B16: BEATRIZ POLLNOW | C16: =IF(ISERROR(SEARCH(" ",TRIM(B16),1)),VLOOKUP(TRIM(B16),[1]!sDados,2,FALSE),VLOOKUP(TRIM(MID(TRIM(B16),1,SEARCH(" ",TRIM(B16),1))),[1]!sDados,2,FALSE)) | E16: 11 | F16: =IF(E16<=18,"00 - 18",IF(E16<=23,"19 - 23",IF(E16<=28,"24 - 28",IF(E16<=33,"29 - 33",IF(E16<=38,"34 - 38",IF(E16<=43,"39 - 43",IF(E16<=48,"44 - 48",IF(E16<=53,"49 - 53",IF(E16<=58,"54 - 58",IF(E16>=59,"59 - ou mais")))))))))) | G16: AMIL S380 QC NAC R COPART PJ | H16: 396.78 | I16: Filho/Filha
A17: T | B17: JOAO VICTOR GAWRON | C17: =IF(ISERROR(SEARCH(" ",TRIM(B17),1)),VLOOKUP(TRIM(B17),[1]!sDados,2,FALSE),VLOOKUP(TRIM(MID(TRIM(B17),1,SEARCH(" ",TRIM(B17),1))),[1]!sDados,2,FALSE)) | E17: 19 | F17: =IF(E17<=18,"00 - 18",IF(E17<=23,"19 - 23",IF(E17<=28,"24 - 28",IF(E17<=33,"29 - 33",IF(E17<=38,"34 - 38",IF(E17<=43,"39 - 43",IF(E17<=48,"44 - 48",IF(E17<=53,"49 - 53",IF(E17<=58,"54 - 58",IF(E17>=59,"59 - ou mais")))))))))) | G17: AMIL S380 QC NAC R COPART PJ | H17: 396.78
A18: T | B18: TIAGO DE BORBA | C18: =IF(ISERROR(SEARCH(" ",TRIM(B18),1)),VLOOKUP(TRIM(B18),[1]!sDados,2,FALSE),VLOOKUP(TRIM(MID(TRIM(B18),1,SEARCH(" ",TRIM(B18),1))),[1]!sDados,2,FALSE)) | E18: 36 | F18: =IF(E18<=18,"00 - 18",IF(E18<=23,"19 - 23",IF(E18<=28,"24 - 28",IF(E18<=33,"29 - 33",IF(E18<=38,"34 - 38",IF(E18<=43,"39 - 43",IF(E18<=48,"44 - 48",IF(E18<=53,"49 - 53",IF(E18<=58,"54 - 58",IF(E18>=59,"59 - ou mais")))))))))) | G18: AMIL S380 QC NAC R COPART PJ | H18: 396.78
A19: D | B19: RAEL COUTINHO DE BORBA | C19: =IF(ISERROR(SEARCH(" ",TRIM(B19),1)),VLOOKUP(TRIM(B19),[1]!sDados,2,FALSE),VLOOKUP(TRIM(MID(TRIM(B19),1,SEARCH(" ",TRIM(B19),1))),[1]!sDados,2,FALSE)) | E19: 3 | F19: =IF(E19<=18,"00 - 18",IF(E19<=23,"19 - 23",IF(E19<=28,"24 - 28",IF(E19<=33,"29 - 33",IF(E19<=38,"34 - 38",IF(E19<=43,"39 - 43",IF(E19<=48,"44 - 48",IF(E19<=53,"49 - 53",IF(E19<=58,"54 - 58",IF(E19>=59,"59 - ou mais")))))))))) | G19: AMIL S380 QC NAC R COPART PJ | H19: 396.78 | I19: Filho/Filha
A20: D | B20: BYANCA VITORIA COUTINHO | C20: =IF(ISERROR(SEARCH(" ",TRIM(B20),1)),VLOOKUP(TRIM(B20),[1]!sDados,2,FALSE),VLOOKUP(TRIM(MID(TRIM(B20),1,SEARCH(" ",TRIM(B20),1))),[1]!sDados,2,FALSE)) | E20: 25 | F20: =IF(E20<=18,"00 - 18",IF(E20<=23,"19 - 23",IF(E20<=28,"24 - 28",IF(E20<=33,"29 - 33",IF(E20<=38,"34 - 38",IF(E20<=43,"39 - 43",IF(E20<=48,"44 - 48",IF(E20<=53,"49 - 53",IF(E20<=58,"54 - 58",IF(E20>=59,"59 - ou mais")))))))))) | G20: AMIL S380 QC NAC R COPART PJ | H20: 396.78 | I20: Conjuge
A21: T | B21: LIANA KEY OKADA NAKAMURA | C21: =IF(ISERROR(SEARCH(" ",TRIM(B21),1)),VLOOKUP(TRIM(B21),[1]!sDados,2,FALSE),VLOOKUP(TRIM(MID(TRIM(B21),1,SEARCH(" ",TRIM(B21),1))),[1]!sDados,2,FALSE)) | E21: 42 | F21: =IF(E21<=18,"00 - 18",IF(E21<=23,"19 - 23",IF(E21<=28,"24 - 28",IF(E21<=33,"29 - 33",IF(E21<=38,"34 - 38",IF(E21<=43,"39 - 43",IF(E21<=48,"44 - 48",IF(E21<=53,"49 - 53",IF(E21<=58,"54 - 58",IF(E21>=59,"59 - ou mais")))))))))) | G21: AMIL S580 QP NAC R COPART PJ | H21: 582.78
A22: T | B22: PRISCILA APARECIDA FARIAS SANTOS | C22: =IF(ISERROR(SEARCH(" ",TRIM(B22),1)),VLOOKUP(TRIM(B22),[1]!sDados,2,FALSE),VLOOKUP(TRIM(MID(TRIM(B22),1,SEARCH(" ",TRIM(B22),1))),[1]!sDados,2,FALSE)) | E22: 45 | F22: =IF(E22<=18,"00 - 18",IF(E22<=23,"19 - 23",IF(E22<=28,"24 - 28",IF(E22<=33,"29 - 33",IF(E22<=38,"34 - 38",IF(E22<=43,"39 - 43",IF(E22<=48,"44 - 48",IF(E22<=53,"49 - 53",IF(E22<=58,"54 - 58",IF(E22>=59,"59 - ou mais")))))))))) | G22: AMIL FÁCIL S80 QC SP RJ DF PR PE GM2 R COPART PJ | H22: 336.51
A23: T | B23: RONALDO DE OLIVEIRA GOMES | C23: =IF(ISERROR(SEARCH(" ",TRIM(B23),1)),VLOOKUP(TRIM(B23),[1]!sDados,2,FALSE),VLOOKUP(TRIM(MID(TRIM(B23),1,SEARCH(" ",TRIM(B23),1))),[1]!sDados,2,FALSE)) | E23: 44 | F23: =IF(E23<=18,"00 - 18",IF(E23<=23,"19 - 23",IF(E23<=28,"24 - 28",IF(E23<=33,"29 - 33",IF(E23<=38,"34 - 38",IF(E23<=43,"39 - 43",IF(E23<=48,"44 - 48",IF(E23<=53,"49 - 53",IF(E23<=58,"54 - 58",IF(E23>=59,"59 - ou mais")))))))))) | G23: AMIL FÁCIL S80 QC SP RJ DF PR PE GM2 R COPART PJ | H23: 336.51
A24: D | B24: GLEYZE FERREIRA DE MATOS GOMES | C24: =IF(ISERROR(SEARCH(" ",TRIM(B24),1)),VLOOKUP(TRIM(B24),[1]!sDados,2,FALSE),VLOOKUP(TRIM(MID(TRIM(B24),1,SEARCH(" ",TRIM(B24),1))),[1]!sDados,2,FALSE)) | E24: 39 | F24: =IF(E24<=18,"00 - 18",IF(E24<=23,"19 - 23",IF(E24<=28,"24 - 28",IF(E24<=33,"29 - 33",IF(E24<=38,"34 - 38",IF(E24<=43,"39 - 43",IF(E24<=48,"44 - 48",IF(E24<=53,"49 - 53",IF(E24<=58,"54 - 58",IF(E24>=59,"59 - ou mais")))))))))) | G24: AMIL FÁCIL S80 QC SP RJ DF PR PE GM2 R COPART PJ | H24: 336.51 | I24: Conjuge
A25: D | B25: SOFYA FERREIRA GOMES | C25: F | E25: 8 | F25: =IF(E25<=18,"00 - 18",IF(E25<=23,"19 - 23",IF(E25<=28,"24 - 28",IF(E25<=33,"29 - 33",IF(E25<=38,"34 - 38",IF(E25<=43,"39 - 43",IF(E25<=48,"44 - 48",IF(E25<=53,"49 - 53",IF(E25<=58,"54 - 58",IF(E25>=59,"59 - ou mais")))))))))) | G25: AMIL FÁCIL S80 QC SP RJ DF PR PE GM2 R COPART PJ | H25: 336.51 | I25: Filho/Filha
A26: T | B26: ANDERSON DE OLIVEIRA PADEIRO | C26: =IF(ISERROR(SEARCH(" ",TRIM(B26),1)),VLOOKUP(TRIM(B26),[1]!sDados,2,FALSE),VLOOKUP(TRIM(MID(TRIM(B26),1,SEARCH(" ",TRIM(B26),1))),[1]!sDados,2,FALSE)) | E26: 53 | F26: =IF(E26<=18,"00 - 18",IF(E26<=23,"19 - 23",IF(E26<=28,"24 - 28",IF(E26<=33,"29 - 33",IF(E26<=38,"34 - 38",IF(E26<=43,"39 - 43",IF(E26<=48,"44 - 48",IF(E26<=53,"49 - 53",IF(E26<=58,"54 - 58",IF(E26>=59,"59 - ou mais")))))))))) | G26: AMIL FÁCIL S80 QC SP RJ DF PR PE GM2 R COPART PJ | H26: 336.51
A27: D | B27: JAQUELINE DIAS DE OLIVEIRA | C27: =IF(ISERROR(SEARCH(" ",TRIM(B27),1)),VLOOKUP(TRIM(B27),[1]!sDados,2,FALSE),VLOOKUP(TRIM(MID(TRIM(B27),1,SEARCH(" ",TRIM(B27),1))),[1]!sDados,2,FALSE)) | E27: 41 | F27: =IF(E27<=18,"00 - 18",IF(E27<=23,"19 - 23",IF(E27<=28,"24 - 28",IF(E27<=33,"29 - 33",IF(E27<=38,"34 - 38",IF(E27<=43,"39 - 43",IF(E27<=48,"44 - 48",IF(E27<=53,"49 - 53",IF(E27<=58,"54 - 58",IF(E27>=59,"59 - ou mais")))))))))) | G27: AMIL FÁCIL S80 QC SP RJ DF PR PE GM2 R COPART PJ | H27: 336.51 | I27: Conjuge
A28: T | B28: MARINA BRAGANCA DE PAULA | C28: =IF(ISERROR(SEARCH(" ",TRIM(B28),1)),VLOOKUP(TRIM(B28),[1]!sDados,2,FALSE),VLOOKUP(TRIM(MID(TRIM(B28),1,SEARCH(" ",TRIM(B28),1))),[1]!sDados,2,FALSE)) | E28: 30 | F28: =IF(E28<=18,"00 - 18",IF(E28<=23,"19 - 23",IF(E28<=28,"24 - 28",IF(E28<=33,"29 - 33",IF(E28<=38,"34 - 38",IF(E28<=43,"39 - 43",IF(E28<=48,"44 - 48",IF(E28<=53,"49 - 53",IF(E28<=58,"54 - 58",IF(E28>=59,"59 - ou mais")))))))))) | G28: AMIL S380 QP NAC R COPART PJ | H28: 440.65
A29: T | B29: LEONARDO OLIVEIRA REIS DE OLIVEIRA CAMINAGUI | C29: =IF(ISERROR(SEARCH(" ",TRIM(B29),1)),VLOOKUP(TRIM(B29),[1]!sDados,2,FALSE),VLOOKUP(TRIM(MID(TRIM(B29),1,SEARCH(" ",TRIM(B29),1))),[1]!sDados,2,FALSE)) | E29: 43 | F29: =IF(E29<=18,"00 - 18",IF(E29<=23,"19 - 23",IF(E29<=28,"24 - 28",IF(E29<=33,"29 - 33",IF(E29<=38,"34 - 38",IF(E29<=43,"39 - 43",IF(E29<=48,"44 - 48",IF(E29<=53,"49 - 53",IF(E29<=58,"54 - 58",IF(E29>=59,"59 - ou mais")))))))))) | G29: AMIL FÁCIL S80 QC SP RJ DF PR PE GM2 R COPART PJ | H29: 336.51
A30: D | B30: VALERIA CAMINAGUI DA SILVA OLIVEIRA | C30: =IF(ISERROR(SEARCH(" ",TRIM(B30),1)),VLOOKUP(TRIM(B30),[1]!sDados,2,FALSE),VLOOKUP(TRIM(MID(TRIM(B30),1,SEARCH(" ",TRIM(B30),1))),[1]!sDados,2,FALSE)) | E30: 41 | F30: =IF(E30<=18,"00 - 18",IF(E30<=23,"19 - 23",IF(E30<=28,"24 - 28",IF(E30<=33,"29 - 33",IF(E30<=38,"34 - 38",IF(E30<=43,"39 - 43",IF(E30<=48,"44 - 48",IF(E30<=53,"49 - 53",IF(E30<=58,"54 - 58",IF(E30>=59,"59 - ou mais")))))))))) | G30: AMIL FÁCIL S80 QC SP RJ DF PR PE GM2 R COPART PJ | H30: 336.51 | I30: Conjuge
A31: D | B31: LUKAS CAMINAGUI DA SILVA OLIVEIRA | C31: =IF(ISERROR(SEARCH(" ",TRIM(B31),1)),VLOOKUP(TRIM(B31),[1]!sDados,2,FALSE),VLOOKUP(TRIM(MID(TRIM(B31),1,SEARCH(" ",TRIM(B31),1))),[1]!sDados,2,FALSE)) | E31: 15 | F31: =IF(E31<=18,"00 - 18",IF(E31<=23,"19 - 23",IF(E31<=28,"24 - 28",IF(E31<=33,"29 - 33",IF(E31<=38,"34 - 38",IF(E31<=43,"39 - 43",IF(E31<=48,"44 - 48",IF(E31<=53,"49 - 53",IF(E31<=58,"54 - 58",IF(E31>=59,"59 - ou mais")))))))))) | G31: AMIL FÁCIL S80 QC SP RJ DF PR PE GM2 R COPART PJ | H31: 336.51 | I31: Filho/Filha
A32: T | B32: JOAO VICTOR LUZ DOS SANTOS | C32: =IF(ISERROR(SEARCH(" ",TRIM(B32),1)),VLOOKUP(TRIM(B32),[1]!sDados,2,FALSE),VLOOKUP(TRIM(MID(TRIM(B32),1,SEARCH(" ",TRIM(B32),1))),[1]!sDados,2,FALSE)) | E32: 23 | F32: =IF(E32<=18,"00 - 18",IF(E32<=23,"19 - 23",IF(E32<=28,"24 - 28",IF(E32<=33,"29 - 33",IF(E32<=38,"34 - 38",IF(E32<=43,"39 - 43",IF(E32<=48,"44 - 48",IF(E32<=53,"49 - 53",IF(E32<=58,"54 - 58",IF(E32>=59,"59 - ou mais")))))))))) | G32: AMIL S380 QP NAC R COPART PJ | H32: 440.65
A33: T | B33: KENNEDY SANTOS COSTA DUARTE | C33: =IF(ISERROR(SEARCH(" ",TRIM(B33),1)),VLOOKUP(TRIM(B33),[1]!sDados,2,FALSE),VLOOKUP(TRIM(MID(TRIM(B33),1,SEARCH(" ",TRIM(B33),1))),[1]!sDados,2,FALSE)) | E33: 22 | F33: =IF(E33<=18,"00 - 18",IF(E33<=23,"19 - 23",IF(E33<=28,"24 - 28",IF(E33<=33,"29 - 33",IF(E33<=38,"34 - 38",IF(E33<=43,"39 - 43",IF(E33<=48,"44 - 48",IF(E33<=53,"49 - 53",IF(E33<=58,"54 - 58",IF(E33>=59,"59 - ou mais")))))))))) | G33: AMIL S380 QP NAC R COPART PJ | H33: 440.65
A34: T | B34: ISAQUE LIMA DA SILVA | C34: =IF(ISERROR(SEARCH(" ",TRIM(B34),1)),VLOOKUP(TRIM(B34),[1]!sDados,2,FALSE),VLOOKUP(TRIM(MID(TRIM(B34),1,SEARCH(" ",TRIM(B34),1))),[1]!sDados,2,FALSE)) | E34: 38 | F34: =IF(E34<=18,"00 - 18",IF(E34<=23,"19 - 23",IF(E34<=28,"24 - 28",IF(E34<=33,"29 - 33",IF(E34<=38,"34 - 38",IF(E34<=43,"39 - 43",IF(E34<=48,"44 - 48",IF(E34<=53,"49 - 53",IF(E34<=58,"54 - 58",IF(E34>=59,"59 - ou mais")))))))))) | G34: AMIL S580 QP NAC R COPART PJ | H34: 582.78
A35: D | B35: ELAINHY DINIZ BEZERRA LIMA | C35: F | E35: 37 | F35: =IF(E35<=18,"00 - 18",IF(E35<=23,"19 - 23",IF(E35<=28,"24 - 28",IF(E35<=33,"29 - 33",IF(E35<=38,"34 - 38",IF(E35<=43,"39 - 43",IF(E35<=48,"44 - 48",IF(E35<=53,"49 - 53",IF(E35<=58,"54 - 58",IF(E35>=59,"59 - ou mais")))))))))) | G35: AMIL S580 QP NAC R COPART PJ | H35: 582.78 | I35: Conjuge
A36: T | B36: RINALDI APARECIDO FRAGOSO | C36: =IF(ISERROR(SEARCH(" ",TRIM(B36),1)),VLOOKUP(TRIM(B36),[1]!sDados,2,FALSE),VLOOKUP(TRIM(MID(TRIM(B36),1,SEARCH(" ",TRIM(B36),1))),[1]!sDados,2,FALSE)) | E36: 48 | F36: =IF(E36<=18,"00 - 18",IF(E36<=23,"19 - 23",IF(E36<=28,"24 - 28",IF(E36<=33,"29 - 33",IF(E36<=38,"34 - 38",IF(E36<=43,"39 - 43",IF(E36<=48,"44 - 48",IF(E36<=53,"49 - 53",IF(E36<=58,"54 - 58",IF(E36>=59,"59 - ou mais")))))))))) | G36: AMIL FÁCIL S80 QC SP RJ DF PR PE GM2 R COPART PJ | H36: 336.51
A37: D | B37: ERICA SOUZA CRUZ FRAGOSO | C37: =IF(ISERROR(SEARCH(" ",TRIM(B37),1)),VLOOKUP(TRIM(B37),[1]!sDados,2,FALSE),VLOOKUP(TRIM(MID(TRIM(B37),1,SEARCH(" ",TRIM(B37),1))),[1]!sDados,2,FALSE)) | E37: 37 | F37: =IF(E37<=18,"00 - 18",IF(E37<=23,"19 - 23",IF(E37<=28,"24 - 28",IF(E37<=33,"29 - 33",IF(E37<=38,"34 - 38",IF(E37<=43,"39 - 43",IF(E37<=48,"44 - 48",IF(E37<=53,"49 - 53",IF(E37<=58,"54 - 58",IF(E37>=59,"59 - ou mais")))))))))) | G37: AMIL FÁCIL S80 QC SP RJ DF PR PE GM2 R COPART PJ | H37: 336.51 | I37: Conjuge
A38: T | B38: APARECIDO DE JESUS OLIVEIRA SILVA | C38: =IF(ISERROR(SEARCH(" ",TRIM(B38),1)),VLOOKUP(TRIM(B38),[1]!sDados,2,FALSE),VLOOKUP(TRIM(MID(TRIM(B38),1,SEARCH(" ",TRIM(B38),1))),[1]!sDados,2,FALSE)) | E38: 34 | F38: =IF(E38<=18,"00 - 18",IF(E38<=23,"19 - 23",IF(E38<=28,"24 - 28",IF(E38<=33,"29 - 33",IF(E38<=38,"34 - 38",IF(E38<=43,"39 - 43",IF(E38<=48,"44 - 48",IF(E38<=53,"49 - 53",IF(E38<=58,"54 - 58",IF(E38>=59,"59 - ou mais")))))))))) | G38: AMIL FÁCIL S80 QC SP RJ DF PR PE GM2 R COPART PJ | H38: 336.51
A39: T | B39: LILIAN BORGES DA SILVA RIOS | C39: =IF(ISERROR(SEARCH(" ",TRIM(B39),1)),VLOOKUP(TRIM(B39),[1]!sDados,2,FALSE),VLOOKUP(TRIM(MID(TRIM(B39),1,SEARCH(" ",TRIM(B39),1))),[1]!sDados,2,FALSE)) | E39: 33 | F39: =IF(E39<=18,"00 - 18",IF(E39<=23,"19 - 23",IF(E39<=28,"24 - 28",IF(E39<=33,"29 - 33",IF(E39<=38,"34 - 38",IF(E39<=43,"39 - 43",IF(E39<=48,"44 - 48",IF(E39<=53,"49 - 53",IF(E39<=58,"54 - 58",IF(E39>=59,"59 - ou mais")))))))))) | G39: AMIL S380 QP NAC R COPART PJ | H39: 440.65
A40: T | B40: KAREN SOUZA BRAGA | C40: =IF(ISERROR(SEARCH(" ",TRIM(B40),1)),VLOOKUP(TRIM(B40),[1]!sDados,2,FALSE),VLOOKUP(TRIM(MID(TRIM(B40),1,SEARCH(" ",TRIM(B40),1))),[1]!sDados,2,FALSE)) | E40: 26 | F40: =IF(E40<=18,"00 - 18",IF(E40<=23,"19 - 23",IF(E40<=28,"24 - 28",IF(E40<=33,"29 - 33",IF(E40<=38,"34 - 38",IF(E40<=43,"39 - 43",IF(E40<=48,"44 - 48",IF(E40<=53,"49 - 53",IF(E40<=58,"54 - 58",IF(E40>=59,"59 - ou mais")))))))))) | G40: AMIL S380 QP NAC R COPART PJ | H40: 440.65
...

Sheet Dinâmica
A3: Rótulos de Linha | B3: Contagem de Plano
A4: AMIL FÁCIL S80 QC SP RJ DF PR PE GM2 R COPART PJ | B4: 66
A5: AMIL ONE S2500 R1 QP NAC PJ | B5: 2
A6: AMIL S380 QC NAC R COPART PJ | B6: 16
A7: AMIL S380 QP NAC R COPART PJ | B7: 30
A8: AMIL S580 QP NAC R COPART PJ | B8: 7
A9: (vazio)
A10: Total Geral | B10: 121

Sheet Perfil Populacional
B3: Faixa Etaria | C3: Titular | E3: Dependentes | G3: Masculino | H3: Feminino
C4: Masculino | D4: Feminino | E4: Masculino | F4: Feminino
B5: 00-18 | C5: 10 | D5: 10 | E5: 3 | F5: 3 | G5: =SUM(C5+E5) | H5: =SUM(D5+F5)
B6: 19-23 | C6: 2 | D6: 21 | G6: =SUM(C6+E6) | H6: =SUM(D6+F6)
B7: 24-28 | C7: 4 | D7: 18 | E7: 1 | F7: 2 | G7: =SUM(C7+E7) | H7: =SUM(D7+F7)
B8: 29-33 | E8: 18 | F8: 12 | G8: =SUM(C8+E8) | H8: =SUM(D8+F8)
B9: 34-38 | C9: 3 | D9: 11 | E9: 1 | F9: 1 | G9: =SUM(C9+E9) | H9: =SUM(D9+F9)
B10: 39-43 | C10: 6 | D10: 15 | E10: 2 | F10: 2 | G10: =SUM(C10+E10) | H10: =SUM(D10+F10)
B11: 44-48 | C11: 9 | D11: 16 | E11: 1 | F11: 5 | G11: =SUM(C11+E11) | H11: =SUM(D11+F11)
B12: 49-53 | C12: 6 | D12: 21 | E12: 2 | F12: 4 | G12: =SUM(C12+E12) | H12: =SUM(D12+F12)
B13: 54-58 | D13: 10 | E13: 4 | G13: =SUM(C13+E13) | H13: =SUM(D13+F13)
B14: 59 + | C14: 8 | D14: 11 | E14: 4 | F14: 3 | G14: =SUM(C14+E14) | H14: =SUM(D14+F14)
B15: Total | C15: =SUM(C5:C14) | D15: =SUM(D5:D14) | E15: =SUM(E5:E14) | F15: =SUM(F5:F14) | G15: =SUM(G5:G14) | H15: =SUM(H5:H14)
B16: Total Geral | C16: =SUM(C15:D15) | E16: =SUM(E15:F15) | G16: =SUM(G15:H15)
B22: Idade Média | C22: =IFERROR(AVERAGE(G5:H14),0) | D22: 37
B23: Titulares | C23: =C16
B24: Dependentes | C24: =E16
B25: Inativos | C25: 0
B26: Sexo Feminino | C26: =IFERROR(E16/G16,0)
B27: Sexo Masculino | C27: =IFERROR(C16/G16,0)
B28: Vidas acima de 59 anos | C28: =IFERROR(SUM(G14:H14)/G16,0)

Sheet Perfil por Localidade
B3: UF | C3: N° Vidas | D3: % | N3: UF | O3: N° Vidas | P3: %
B4: AC | D4: =Tabela1[[#This Row],[N° Vidas]]/SUM(Tabela1[N° Vidas]) | N4: {=IFERROR(INDEX($B$4:$B$30,_xlfn.AGGREGATE(15,6,ROW($B$4:$B$30)-ROW($B$3)/($C$4:$C$30>0),ROW(A1))), "")} | O4: =IFERROR(INDEX($C$4:$C$30,MATCH(N4,$B$4:$B$30,0)), "") | P4: =IFERROR(O4/$C$32, "")
B5: AL | D5: =Tabela1[[#This Row],[N° Vidas]]/SUM(Tabela1[N° Vidas]) | N5: {=IFERROR(INDEX($B$4:$B$30,_xlfn.AGGREGATE(15,6,ROW($B$4:$B$30)-ROW($B$3)/($C$4:$C$30>0),ROW(A2))), "")} | O5: =IFERROR(INDEX($C$4:$C$30,MATCH(N5,$B$4:$B$30,0)), "") | P5: =IFERROR(O5/$C$32, "")
B6: AM | D6: =Tabela1[[#This Row],[N° Vidas]]/SUM(Tabela1[N° Vidas]) | N6: {=IFERROR(INDEX($B$4:$B$30,_xlfn.AGGREGATE(15,6,ROW($B$4:$B$30)-ROW($B$3)/($C$4:$C$30>0),ROW(A3))), "")} | O6: =IFERROR(INDEX($C$4:$C$30,MATCH(N6,$B$4:$B$30,0)), "") | P6: =IFERROR(O6/$C$32, "")
B7: AP | D7: =Tabela1[[#This Row],[N° Vidas]]/SUM(Tabela1[N° Vidas]) | N7: {=IFERROR(INDEX($B$4:$B$30,_xlfn.AGGREGATE(15,6,ROW($B$4:$B$30)-ROW($B$3)/($C$4:$C$30>0),ROW(A4))), "")} | O7: =IFERROR(INDEX($C$4:$C$30,MATCH(N7,$B$4:$B$30,0)), "") | P7: =IFERROR(O7/$C$32, "")
B8: BA | D8: =Tabela1[[#This Row],[N° Vidas]]/SUM(Tabela1[N° Vidas]) | N8: {=IFERROR(INDEX($B$4:$B$30,_xlfn.AGGREGATE(15,6,ROW($B$4:$B$30)-ROW($B$3)/($C$4:$C$30>0),ROW(A5))), "")} | O8: =IFERROR(INDEX($C$4:$C$30,MATCH(N8,$B$4:$B$30,0)), "") | P8: =IFERROR(O8/$C$32, "")
B9: CE | D9: =Tabela1[[#This Row],[N° Vidas]]/SUM(Tabela1[N° Vidas]) | N9: {=IFERROR(INDEX($B$4:$B$30,_xlfn.AGGREGATE(15,6,ROW($B$4:$B$30)-ROW($B$3)/($C$4:$C$30>0),ROW(A6))), "")} | O9: =IFERROR(INDEX($C$4:$C$30,MATCH(N9,$B$4:$B$30,0)), "") | P9: =IFERROR(O9/$C$32, "")
B10: DF | D10: =Tabela1[[#This Row],[N° Vidas]]/SUM(Tabela1[N° Vidas]) | N10: {=IFERROR(INDEX($B$4:$B$30,_xlfn.AGGREGATE(15,6,ROW($B$4:$B$30)-ROW($B$3)/($C$4:$C$30>0),ROW(A7))), "")} | O10: =IFERROR(INDEX($C$4:$C$30,MATCH(N10,$B$4:$B$30,0)), "") | P10: =IFERROR(O10/$C$32, "")
B11: ES | D11: =Tabela1[[#This Row],[N° Vidas]]/SUM(Tabela1[N° Vidas]) | N11: {=IFERROR(INDEX($B$4:$B$30,_xlfn.AGGREGATE(15,6,ROW($B$4:$B$30)-ROW($B$3)/($C$4:$C$30>0),ROW(A8))), "")} | O11: =IFERROR(INDEX($C$4:$C$30,MATCH(N11,$B$4:$B$30,0)), "") | P11: =IFERROR(O11/$C$32, "")
B12: GO | D12: =Tabela1[[#This Row],[N° Vidas]]/SUM(Tabela1[N° Vidas]) | N12: {=IFERROR(INDEX($B$4:$B$30,_xlfn.AGGREGATE(15,6,ROW($B$4:$B$30)-ROW($B$3)/($C$4:$C$30>0),ROW(A9))), "")} | O12: =IFERROR(INDEX($C$4:$C$30,MATCH(N12,$B$4:$B$30,0)), "") | P12: =IFERROR(O12/$C$32, "")
B13: MA | D13: =Tabela1[[#This Row],[N° Vidas]]/SUM(Tabela1[N° Vidas]) | N13: {=IFERROR(INDEX($B$4:$B$30,_xlfn.AGGREGATE(15,6,ROW($B$4:$B$30)-ROW($B$3)/($C$4:$C$30>0),ROW(A10))), "")} | O13: =IFERROR(INDEX($C$4:$C$30,MATCH(N13,$B$4:$B$30,0)), "") | P13: =IFERROR(O13/$C$32, "")
B14: MG | D14: =Tabela1[[#This Row],[N° Vidas]]/SUM(Tabela1[N° Vidas]) | N14: {=IFERROR(INDEX($B$4:$B$30,_xlfn.AGGREGATE(15,6,ROW($B$4:$B$30)-ROW($B$3)/($C$4:$C$30>0),ROW(A11))), "")} | O14: =IFERROR(INDEX($C$4:$C$30,MATCH(N14,$B$4:$B$30,0)), "") | P14: =IFERROR(O14/$C$32, "")
B15: MS | D15: =Tabela1[[#This Row],[N° Vidas]]/SUM(Tabela1[N° Vidas]) | N15: {=IFERROR(INDEX($B$4:$B$30,_xlfn.AGGREGATE(15,6,ROW($B$4:$B$30)-ROW($B$3)/($C$4:$C$30>0),ROW(A12))), "")} | O15: =IFERROR(INDEX($C$4:$C$30,MATCH(N15,$B$4:$B$30,0)), "") | P15: =IFERROR(O15/$C$32, "")
... B30: TO | D30: =Tabela1[[#This Row],[N° Vidas]]/SUM(Tabela1[N° Vidas]) | N30: {=IFERROR(INDEX($B$4:$B$30,_xlfn.AGGREGATE(15,6,ROW($B$4:$B$30)-ROW($B$3)/($C$4:$C$30>0),ROW(A27))), "")} | O30: =IFERROR(INDEX($C$4:$C$30,MATCH(N30,$B$4:$B$30,0)), "") | P30: =IFERROR(O30/$C$32, "")
B32: Total de Vidas | C32: =SUM(Tabela1[N° Vidas])

Sheet Equivalência
B1: Amil | C1: Player I | D1: Player II | E1: Player III | F1: Player IV | O1: a | P1: r
A3: Produto | B3: Produto 1 | C3: Produto | D3: Produto | E3: Produto | F3: Produto
A4: Acomodação | C4: a
A5: Abrangência Nacional
A6: Reembolso - Consulta | B6: R$ | C6: R$ | D6: R$ | E6: R$ | F6: R$
A8: Produto | B8: Produto 2 | C8: Produto | D8: Produto | E8: Produto | F8: Produto
A9: Acomodação | C9: r | D9: a
A10: Abrangência Nacional
A11: Reembolso - Consulta | B11: R$ | C11: R$ | D11: R$ | E11: R$ | F11: R$
A13: Produto | B13: Produto 3 | C13: Produto | D13: Produto | E13: Produto | F13: Produto
A14: Acomodação
A15: Abrangência Nacional
A16: Reembolso - Consulta | B16: R$ | C16: R$ | D16: R$ | E16: R$ | F16: R$
A18: Produto | B18: Produto 4 | C18: Produto | D18: Produto | E18: Produto | F18: Produto
A19: Acomodação
A20: Abrangência Nacional
A21: Reembolso - Consulta | B21: R$ | C21: R$ | D21: R$ | E21: R$ | F21: R$
A23: Produto | B23: Produto 5 | C23: Produto | D23: Produto | E23: Produto | F23: Produto
A24: Acomodação
A25: Abrangência Nacional
A26: Reembolso - Consulta | B26: R$ | C26: R$ | D26: R$ | E26: R$ | F26: R$
A28: Produto | B28: Produto 6 | C28: Produto | D28: Produto | E28: Produto | F28: Produto
A29: Acomodação
A30: Abrangência Nacional
A31: Reembolso - Consulta | B31: R$ | C31: R$ | D31: R$ | E31: R$ | F31: R$
A33: Produto | B33: Produto 7 | C33: Produto | D33: Produto | E33: Produto | F33: Produto
A34: Acomodação
A35: Abrangência Nacional
A36: Reembolso - Consulta | B36: R$ | C36: R$ | D36: R$ | E36: R$ | F36: R$
A38: Produto | B38: Produto 8 | C38: Produto | D38: Produto | E38: Produto | F38: Produto
A39: Acomodação
A40: Abrangência Nacional
A41: Reembolso - Consulta | B41: R$ | C41: R$ | D41: R$ | E41: R$ | F41: R$
A43: Produto | B43: Produto 9 | C43: Produto | D43: Produto | E43: Produto | F43: Produto
A44: Acomodação
A45: Abrangência Nacional
A46: Reembolso - Consulta | B46: R$ | C46: R$ | D46: R$ | E46: R$ | F46: R$
A48: Produto | B48: Produto 10 | C48: Produto | D48: Produto | E48: Produto | F48: Produto
A49: Acomodação
A50: Abrangência Nacional
...

Sheet Análise Financeira
B1: Amil | C1: Reajuste 20% | D1: Player I | E1: Player II | F1: Player III | G1: Player IV | Q1: a | R1: r
A3: Produto | B3: Produto 1 | C3: =B3 | D3: Produto | E3: Produto | F3: Produto | G3: Produto
A4: Número de Vidas | B4: 120 | C4: =B4 | D4: =C4 | E4: =D4 | F4: =E4 | G4: =F4
A5: Custo Médio | B5: 130 | C5: =B5*120% | D5: 115 | E5: 100 | F5: 200 | G5: 210
A6: Total | B6: =B5*B4 | C6: =C5*C4 | D6: =D5*D4 | E6: =E5*E4 | F6: =F5*F4 | G6: =G5*G4
A8: Produto | B8: Produto 2 | C8: =B8 | D8: Produto | E8: Produto | F8: Produto | G8: Produto
A9: Número de Vidas | C9: =B9 | D9: =C9 | E9: =D9 | F9: =E9 | G9: =F9
A10: Custo Médio | C10: =B10*120%
A11: Total | B11: =B10*B9 | C11: =C10*C9 | D11: =D10*D9 | E11: =E10*E9 | F11: =F10*F9 | G11: =G10*G9
A13: Produto | B13: Produto 3 | C13: =B13 | D13: Produto | E13: Produto | F13: Produto | G13: Produto
A14: Número de Vidas | C14: =B14 | D14: =C14 | E14: =D14 | F14: =E14 | G14: =F14
A15: Custo Médio | C15: =B15*120%
A16: Total | B16: =B15*B14 | C16: =C15*C14 | D16: =D15*D14 | E16: =E15*E14 | F16: =F15*F14 | G16: =G15*G14
A18: Produto | B18: Produto 4 | C18: =B18 | D18: Produto | E18: Produto | F18: Produto | G18: Produto
A19: Número de Vidas | C19: =B19 | D19: =C19 | E19: =D19 | F19: =E19 | G19: =F19
A20: Custo Médio | C20: =B20*120%
A21: Total | B21: =B20*B19 | C21: =C20*C19 | D21: =D20*D19 | E21: =E20*E19 | F21: =F20*F19 | G21: =G20*G19
A23: Produto | B23: Produto 5 | C23: =B23 | D23: Produto | E23: Produto | F23: Produto | G23: Produto
A24: Número de Vidas | C24: =B24 | D24: =C24 | E24: =D24 | F24: =E24 | G24: =F24
A25: Custo Médio | C25: =B25*120%
A26: Total | B26: =B25*B24 | C26: =C25*C24 | D26: =D25*D24 | E26: =E25*E24 | F26: =F25*F24 | G26: =G25*G24
A28: Produto | B28: Produto 6 | C28: =B28 | D28: Produto | E28: Produto | F28: Produto | G28: Produto
A29: Número de Vidas | C29: =B29 | D29: =C29 | E29: =D29 | F29: =E29 | G29: =F29
A30: Custo Médio | C30: =B30*120%
A31: Total | B31: =B30*B29 | C31: =C30*C29 | D31: =D30*D29 | E31: =E30*E29 | F31: =F30*F29 | G31: =G30*G29
A33: Produto | B33: Produto 7 | C33: =B33 | D33: Produto | E33: Produto | F33: Produto | G33: Produto
A34: Número de Vidas | C34: =B34 | D34: =C34 | E34: =D34 | F34: =E34 | G34: =F34
A35: Custo Médio | C35: =B35*120%
A36: Total | B36: =B35*B34 | C36: =C35*C34 | D36: =D35*D34 | E36: =E35*E34 | F36: =F35*F34 | G36: =G35*G34
A38: Produto | B38: Produto 8 | C38: =B38 | D38: Produto | E38: Produto | F38: Produto | G38: Produto
A39: Número de Vidas | C39: =B39 | D39: =C39 | E39: =D39 | F39: =E39 | G39: =F39
A40: Custo Médio | C40: =B40*120%
A41: Total | B41: =B40*B39 | C41: =C40*C39 | D41: =D40*D39 | E41: =E40*E39 | F41: =F40*F39 | G41: =G40*G39
A43: Produto | B43: Produto 9 | C43: =B43 | D43: Produto | E43: Produto | F43: Produto | G43: Produto
A44: Número de Vidas | C44: =B44 | D44: =C44 | E44: =D44 | F44: =E44 | G44: =F44
A45: Custo Médio | C45: =B45*120%
A46: Total | B46: =B45*B44 | C46: =C45*C44 | D46: =D45*D44 | E46: =E45*E44 | F46: =F45*F44 | G46: =G45*G44
A48: Produto | B48: Produto 10 | C48: =B48 | D48: Produto | E48: Produto | F48: Produto | G48: Produto
A49: Número de Vidas | C49: =B49 | D49: =C49 | E49: =D49 | F49: =E49 | G49: =F49
A50: Custo Médio | C50: =B50*120%
...

Sheet Impacto Financeiro
B1: Amil | C1: Reajuste 20% | D1: Player I | E1: Player II | F1: Player III | G1: Player IV | Q1: a | R1: r
A3: Total de Vidas | B3: ='Análise Financeira'!B4 | C3: ='Análise Financeira'!C4 | D3: ='Análise Financeira'!D4 | E3: ='Análise Financeira'!E4 | F3: ='Análise Financeira'!F4 | G3: ='Análise Financeira'!G4
A4: Total da Fatura (Mensal) | B4: ='Análise Financeira'!B6 | C4: ='Análise Financeira'!C6 | D4: ='Análise Financeira'!D6 | E4: ='Análise Financeira'!E6 | F4: ='Análise Financeira'!F6 | G4: ='Análise Financeira'!G6
A5: Total da Fatura (Anual) | B5: =B4*12 | C5: =C4*12 | D5: =D4*12 | E5: =E4*12 | F5: =F4*12 | G5: =G4*12
A6: Impacto Financeiro (Mensal) | C6: =C4-B4 | D6: =D4-$C$4 | E6: =E4-$C$4 | F6: =F4-$C$4 | G6: =G4-$C$4
A7: Impacto Financeiro (Anual) | C7: =C5-B5 | D7: =D5-$C$5 | E7: =E5-$C$5 | F7: =F5-$C$5 | G7: =G5-$C$5
A8: Impacto Financeiro ( em %) | C8: =C5/B5-1 | D8: =D5/$C$5-1 | E8: =E5/$C$5-1 | F8: =F5/$C$5-1 | G8: =G5/$C$5-1

Sheet Custo Faixa Etária
B3: idade
B5: 00 a 18 | C5: 0 | D5: 0 | E5: 0 | F5: 0 | G5: 0 | H5: 0 | I5: 0
B6: 19 a 23 | C6: 0 | D6: 0 | E6: 0 | F6: 0 | G6: 0 | H6: 0 | I6: 0
B7: 24 a 28 | C7: 0 | D7: 0 | E7: 0 | F7: 0 | G7: 0 | H7: 0 | I7: 0
B8: 29 a 33 | C8: 0 | D8: 0 | E8: 0 | F8: 0 | G8: 0 | H8: 0 | I8: 0
B9: 34 a 38 | C9: 0 | D9: 0 | E9: 0 | F9: 0 | G9: 0 | H9: 0 | I9: 0
B10: 39 a 43 | C10: 0 | D10: 0 | E10: 0 | F10: 0 | G10: 0 | H10: 0 | I10: 0
B11: 44 a 48 | C11: 0 | D11: 0 | E11: 0 | F11: 0 | G11: 0 | H11: 0 | I11: 0
B12: 49 a 53 | C12: 0 | D12: 0 | E12: 0 | F12: 0 | G12: 0 | H12: 0 | I12: 0
B13: 54 a 58 | C13: 0 | D13: 0 | E13: 0 | F13: 0 | G13: 0 | H13: 0 | I13: 0
B14: 59 ou + | C14: 0 | D14: 0 | E14: 0 | F14: 0 | G14: 0 | H14: 0 | I14: 0

Sheet Modelo de Coparticipação
B3: Modelo de Coparticipação
B4: Pronto Socorro
B5: Consulta médica / Telemedicina
B6: Exames Simples
B7: Exames Especiais
B8: Terapias Simples
B9: Terapias Especiais
B10: Internação

Sheet Condições
B2: Condições
B3: Afastadados
B4: Crônicos
B5: Agregados
B6: Demitidos / Aposentados
B7: Prestadores
B8: Vigência do Contrato

Sheet DIferenciais

Sheet Rede Credenciada
B2: Prestadores | C2: Localidade | D2: Plano | E2: Plano | F2: Plano | G2: Plano
D3: P
D4: P
